<mujoco model="car">
  <compiler inertiafromgeom="true"/>
  <option timestep="0.002" gravity="0 0 -9.81"/>

  <asset>
    <texture name="grid" type="2d" builtin="checker"
             rgb1="0.2 0.3 0.4" rgb2="0.8 0.8 0.8"
             width="512" height="512"/>
    <material name="grid_mat" texture="grid" texrepeat="5 5"
              specular="0.3" shininess="0.3"/>
    <texture name="wheel_pattern" type="2d" builtin="checker"
             rgb1="1 1 1" rgb2="0 0 0"
             width="64" height="64"/>
    <material name="wheel_mat" texture="wheel_pattern" texrepeat="8 1"
              specular="0.5" shininess="0.5"/>
  </asset>

  <worldbody>
    <geom name="floor" type="plane" size="150 150 0.3"
          rgba="0.8 0.8 0.8 1" material="grid_mat"
          friction="1.0 0.01 0.001"/>

    <body name="chassis" pos="0 0 0.4">
      <inertial pos="0.15 0 0" mass="1500" diaginertia="460 2160 1000"/>
      <joint name="x_slide" type="slide" axis="1 0 0" damping="0.1"/>
      <joint name="z_slide" type="slide" axis="0 0 1" damping="0.1"/>
      <joint name="roll" type="hinge" axis="1 0 0" damping="0.1"/>
      <joint name="pitch" type="hinge" axis="0 1 0" damping="0.1"/>

      <geom name="chassis_geom" type="box" size="1.55 1.5 0.09"
            rgba="1 0 0 1"/>

      <site name="driver_seat" pos="0.15 0.75 0.09" size="0.015"
            rgba="1 0 1 0.5"/>

      <site name="lidar_left" pos="0.15 2 0.5" size="0.01"
            rgba="1 0 0 1"/>
      <site name="lidar_right" pos="0.15 -2 0.5" size="0.01"
            rgba="1 0 0 1"/>


      <!-- Front Left Suspension & Wheel -->
      <body name="fl_susp" pos="1.55 1.65 0.0">
        <inertial pos="0 0 0" mass="25" diaginertia="0.001 0.001 0.001"/>
        <joint name="fl_suspension" type="slide" axis="0 0 1" damping="1000" range="-0.1 0.1"/>
        <body name="front_left_wheel" pos="0 0 -0.09">
          <joint name="fl_wheel" type="hinge" axis="0 1 0" damping="0.01"/>
          <geom name="fl_geom" type="cylinder" size="0.3 0.09"
                euler="90 0 0" material="wheel_mat" mass="35"
                friction="1.0 0.01 0.001"/>
        </body>
      </body>

      <!-- Front Right Suspension & Wheel -->
      <body name="fr_susp" pos="1.55 -1.65 0.0">
        <inertial pos="0 0 0" mass="25" diaginertia="0.001 0.001 0.001"/>
        <joint name="fr_suspension" type="slide" axis="0 0 1" damping="1000" range="-0.1 0.1"/>
        <body name="front_right_wheel" pos="0 0 -0.09">
          <joint name="fr_wheel" type="hinge" axis="0 1 0" damping="0.01"/>
          <geom name="fr_geom" type="cylinder" size="0.3 0.09"
                euler="90 0 0" material="wheel_mat" mass="35"
                friction="1.0 0.01 0.001"/>
        </body>
      </body>

      <!-- Rear Left Suspension & Wheel -->
      <body name="rl_susp" pos="-1.55 1.65 0.0">
        <inertial pos="0 0 0" mass="25" diaginertia="0.001 0.001 0.001"/>
        <joint name="rl_suspension" type="slide" axis="0 0 1" damping="1000" range="-0.1 0.1"/>
        <body name="rear_left_wheel" pos="0 0 -0.09">
          <joint name="rl_wheel" type="hinge" axis="0 1 0" damping="0.01"/>
          <geom name="rl_geom" type="cylinder" size="0.3 0.09"
                euler="90 0 0" material="wheel_mat" mass="35"
                friction="1.0 0.01 0.001"/>
        </body>
      </body>

      <!-- Rear Right Suspension & Wheel -->
      <body name="rr_susp" pos="-1.55 -1.65 0.0">
        <inertial pos="0 0 0" mass="25" diaginertia="0.001 0.001 0.001"/>
        <joint name="rr_suspension" type="slide" axis="0 0 1" damping="1000" range="-0.1 0.1"/>
        <body name="rear_right_wheel" pos="0 0 -0.09">
          <joint name="rr_wheel" type="hinge" axis="0 1 0" damping="0.01"/>
          <geom name="rr_geom" type="cylinder" size="0.3 0.09"
                euler="90 0 0" material="wheel_mat" mass="35"
                friction="1.0 0.01 0.001"/>
        </body>
      </body>

    </body>
  </worldbody>

  <sensor>
    <accelerometer name="accel_z" site="driver_seat"/>
    <gyro name="gyro_pitch" site="driver_seat"/>
    <framepos name="lidar_left_pos" objtype="site" objname="lidar_left"/>
    <framepos name="lidar_right_pos" objtype="site" objname="lidar_right"/>
  </sensor>

  <actuator>
    <motor name="fl_motor" joint="fl_wheel" ctrlrange="-10 10" gear="1.0"/>
    <motor name="fr_motor" joint="fr_wheel" ctrlrange="-10 10" gear="1.0"/>
    <motor name="rl_motor" joint="rl_wheel" ctrlrange="-10 10" gear="1.0"/>
    <motor name="rr_motor" joint="rr_wheel" ctrlrange="-10 10" gear="1.0"/>

    <general name="fl_spring" joint="fl_suspension" gainprm="0 0 0" biasprm="0 35000 1000"/>
    <general name="fr_spring" joint="fr_suspension" gainprm="0 0 0" biasprm="0 35000 1000"/>
    <general name="rl_spring" joint="rl_suspension" gainprm="0 0 0" biasprm="0 38000 1100"/>
    <general name="rr_spring" joint="rr_suspension" gainprm="0 0 0" biasprm="0 38000 1100"/>
  </actuator>
</mujoco>